FakeGeoLocatorRepository: locationServiceEnabled: true, permission: LocationPermission.always, throwError: false
Current state: AsyncData<LatLng?>(value: LatLng(33.150691628036256, 73.74845167724608))
Current state: AsyncData<LatLng?>(value: LatLng(33.150691628036256, 73.74845167724608))
Current state: AsyncData<LatLng?>(value: LatLng(33.150691628036256, 73.74845167724608))
Current state: AsyncData<LatLng?>(value: LatLng(33.150691628036256, 73.74845167724608))
Current state: AsyncData<LatLng?>(value: LatLng(33.150691628036256, 73.74845167724608))
Current state: AsyncData<LatLng?>(value: LatLng(33.150691628036256, 73.74845167724608))
Current state: AsyncData<LatLng?>(value: LatLng(33.150691628036256, 73.74845167724608))
Current state: AsyncData<LatLng?>(value: LatLng(33.150691628036256, 73.74845167724608))
Current state: AsyncData<LatLng?>(value: LatLng(33.150691628036256, 73.74845167724608))
Current state: AsyncData<LatLng?>(value: LatLng(33.150691628036256, 73.74845167724608))
Current state: AsyncData<LatLng?>(value: LatLng(33.150691628036256, 73.74845167724608))
Current state: AsyncData<LatLng?>(value: LatLng(33.150691628036256, 73.74845167724608))
Current state: AsyncData<LatLng?>(value: LatLng(33.150691628036256, 73.74845167724608))
Current state: AsyncData<LatLng?>(value: LatLng(33.150691628036256, 73.74845167724608))
Current state: AsyncData<LatLng?>(value: LatLng(33.150691628036256, 73.74845167724608))
Current state: AsyncData<LatLng?>(value: LatLng(33.150691628036256, 73.74845167724608))
Current state: AsyncData<LatLng?>(value: LatLng(33.150691628036256, 73.74845167724608))
Current state: AsyncData<LatLng?>(value: LatLng(33.150691628036256, 73.74845167724608))
Current state: AsyncData<LatLng?>(value: LatLng(33.150691628036256, 73.74845167724608))
Current state: AsyncData<LatLng?>(value: LatLng(33.150691628036256, 73.74845167724608))
Current state: AsyncData<LatLng?>(value: LatLng(33.150691628036256, 73.74845167724608))
Current state: AsyncData<LatLng?>(value: LatLng(33.150691628036256, 73.74845167724608))
Current state: AsyncData<LatLng?>(value: LatLng(33.150691628036256, 73.74845167724608))
Current state: AsyncData<LatLng?>(value: LatLng(33.150691628036256, 73.74845167724608))
Current state: AsyncData<LatLng?>(value: LatLng(33.150691628036256, 73.74845167724608))
Current state: AsyncData<LatLng?>(value: LatLng(33.150691628036256, 73.74845167724608))
Current state: AsyncData<LatLng?>(value: LatLng(33.150691628036256, 73.74845167724608))
Current state: AsyncData<LatLng?>(value: LatLng(33.150691628036256, 73.74845167724608))
Current state: AsyncData<LatLng?>(value: LatLng(33.150691628036256, 73.74845167724608))
Current state: AsyncData<LatLng?>(value: LatLng(33.150691628036256, 73.74845167724608))
Current state: AsyncData<LatLng?>(value: LatLng(33.150691628036256, 73.74845167724608))
Current state: AsyncData<LatLng?>(value: LatLng(33.150691628036256, 73.74845167724608))
Current state: AsyncData<LatLng?>(value: LatLng(33.150691628036256, 73.74845167724608))
Current state: AsyncData<LatLng?>(value: LatLng(33.150691628036256, 73.74845167724608))
Current state: AsyncData<LatLng?>(value: LatLng(33.150691628036256, 73.74845167724608))
Current state: AsyncData<LatLng?>(value: LatLng(33.150691628036256, 73.74845167724608))
Current state: AsyncData<LatLng?>(value: LatLng(33.150691628036256, 73.74845167724608))
Current state: AsyncData<LatLng?>(value: LatLng(33.150691628036256, 73.74845167724608))
Current state: AsyncData<LatLng?>(value: LatLng(33.150691628036256, 73.74845167724608))
Current state: AsyncData<LatLng?>(value: LatLng(33.150691628036256, 73.74845167724608))
Current state: AsyncData<LatLng?>(value: LatLng(33.150691628036256, 73.74845167724608))
Current state: AsyncData<LatLng?>(value: LatLng(33.150691628036256, 73.74845167724608))
══╡ EXCEPTION CAUGHT BY FLUTTER TEST FRAMEWORK ╞════════════════════════════════════════════════════
The following TestFailure was thrown while running async test code:
UserLocationController did not enter error state within timeout.
When the exception was thrown, this was the stack:
#0      fail (package:matcher/src/expect/expect.dart:149:31)
#1      main.<anonymous closure>.<anonymous closure>.<anonymous closure>.<anonymous closure> (file:///D:/Flutter%20Apps/City%20Helper%20System/app/integration_test/startup_flow_test.dart:73:11)
<asynchronous suspension>
#7      main.<anonymous closure>.<anonymous closure>.<anonymous closure> (file:///D:/Flutter%20Apps/City%20Helper%20System/app/integration_test/startup_flow_test.dart:68:9)
<asynchronous suspension>
#8      LiveTestWidgetsFlutterBinding.runAsync (package:flutter_test/src/binding.dart:2121:14)
<asynchronous suspension>
#9      main.<anonymous closure>.<anonymous closure> (file:///D:/Flutter%20Apps/City%20Helper%20System/app/integration_test/startup_flow_test.dart:46:7)
<asynchronous suspension>
#10     testWidgets.<anonymous closure>.<anonymous closure> (package:flutter_test/src/widget_tester.dart:193:15)
<asynchronous suspension>
#11     TestWidgetsFlutterBinding._runTestBody (package:flutter_test/src/binding.dart:1064:5)
<asynchronous suspension>
<asynchronous suspension>
(elided 6 frames from dart:async and package:stack_trace)
════════════════════════════════════════════════════════════════════════════════════════════════════
══╡ EXCEPTION CAUGHT BY FLUTTER TEST FRAMEWORK ╞════════════════════════════════════════════════════
The following assertion was thrown running a test:
Asynchronous call to guarded function leaked.
You must use "await" with all Future-returning test APIs.
The guarded method "pumpAndSettle" from class WidgetTester was called from
file:///D:/Flutter%20Apps/City%20Helper%20System/app/integration_test/startup_flow_test.dart on line
69, but never completed before its parent scope closed.
The guarded method "pump" from class LiveTestWidgetsFlutterBinding was called from
package:flutter_test/src/widget_tester.dart on line 720, but never completed before its parent scope
closed.
When the exception was thrown, this was the stack:
#0      TestAsyncUtils.verifyAllScopesClosed (package:flutter_test/src/test_async_utils.dart:342:7)
#1      TestWidgetsFlutterBinding.asyncBarrier (package:flutter_test/src/binding.dart:808:20)
#2      TestWidgetsFlutterBinding._runTestBody (package:flutter_test/src/binding.dart:1065:5)
<asynchronous suspension>
<asynchronous suspension>
(elided one frame from package:stack_trace)
The test description was:
  Shows error when location services are disabled (Desktop Flow)
════════════════════════════════════════════════════════════════════════════════════════════════════
══╡ EXCEPTION CAUGHT BY FLUTTER TEST FRAMEWORK ╞════════════════════════════════════════════════════
The following message was thrown:
Multiple exceptions (2) were detected during the running of the current test, and at least one was
unexpected.
════════════════════════════════════════════════════════════════════════════════════════════════════
'package:flutter_test/src/binding.dart': Failed assertion: line 2168 pos 12: '_pendingFrame == null': is not true.
dart:core                                                                                                       _AssertionError._throwNew
package:flutter_test/src/binding.dart 2168:12                                                                   LiveTestWidgetsFlutterBinding.postTest
===== asynchronous gap ===========================
package:stream_channel                                                                                          _GuaranteeSink.add
c:/Users/BILAWA~1/AppData/Local/Temp/flutter_tools.ea4d4147/flutter_test_listener.39717c4e/listener.dart 56:22  main.<fn>
Current state: AsyncData<LatLng?>(value: LatLng(33.150691628036256, 73.74845167724608))